<?xml version="1.0" encoding="UTF-8"?>
<robot xmlns:xacro="http://ros.org/wiki/xacro" name="AchileMKinect">
    <link name="pelvis">
        <collision>
            <origin xyz="0.027581 -0.003062 -0.037279" rpy="0.000000 0.000000 90.000000"/>
            <geometry>
                <cylinder radius="0.181900" length="0.297400"/>
            </geometry>
        </collision>
        <visual>
            <origin xyz="0.000000 0.000000 0.000000" rpy="0.000000 0.000000 0.000000"/>
            <geometry>
                <mesh filename="package://human_model/meshes/pelvis-polyhedre1.dae"/>
            </geometry>
            <material name="pelvis_polyhedre1">
                <color rgba="0.901961 0.772549 0.694118 1.000000"/>
            </material>
        </visual>
        <visual>
            <origin xyz="0.000000 0.000000 0.000000" rpy="0.000000 0.000000 0.000000"/>
            <geometry>
                <mesh filename="package://human_model/meshes/pelvis-polyhedre2.dae"/>
            </geometry>
            <material name="pelvis_polyhedre2">
                <color rgba="0.992157 0.466667 0.466667 1.000000"/>
            </material>
        </visual>
        <visual>
            <origin xyz="0.000000 0.000000 0.000000" rpy="0.000000 0.000000 0.000000"/>
            <geometry>
                <mesh filename="package://human_model/meshes/pelvis-polyhedre3.dae"/>
            </geometry>
            <material name="pelvis_polyhedre3">
                <color rgba="0.190401 0.311497 0.805370 1.000000"/>
            </material>
        </visual>
        <visual>
            <origin xyz="0.000000 0.000000 0.000000" rpy="0.000000 0.000000 0.000000"/>
            <geometry>
                <mesh filename="package://human_model/meshes/pelvis-polyhedre4.dae"/>
            </geometry>
            <material name="pelvis_polyhedre4">
                <color rgba="0.323049 0.186374 0.136675 1.000000"/>
            </material>
        </visual>
        <visual>
            <origin xyz="0.000000 0.000000 0.000000" rpy="0.000000 0.000000 0.000000"/>
            <geometry>
                <mesh filename="package://human_model/meshes/pelvis-polyhedre5.dae"/>
            </geometry>
            <material name="pelvis_polyhedre5">
                <color rgba="0.062745 0.545098 0.796078 1.000000"/>
            </material>
        </visual>
        <visual>
            <origin xyz="0.000000 0.000000 0.000000" rpy="0.000000 0.000000 0.000000"/>
            <geometry>
                <mesh filename="package://human_model/meshes/pelvis-polyhedre6.dae"/>
            </geometry>
            <material name="pelvis_polyhedre6">
                <color rgba="1.000000 0.882353 0.000000 1.000000"/>
            </material>
        </visual>
    </link>
    <link name="pelvis+TorsoY">
        <collision>
            <origin xyz="0.027581 -0.003062 -0.037279" rpy="0.000000 0.000000 90.000000"/>
            <geometry>
                <cylinder radius="0.181900" length="0.297400"/>
            </geometry>
        </collision>
        <visual>
            <origin xyz="0.000000 0.000000 0.000000" rpy="0.000000 0.000000 0.000000"/>
            <geometry>
                <mesh filename="package://human_model/meshes/pelvis-polyhedre1.dae"/>
            </geometry>
            <material name="pelvis_polyhedre1">
                <color rgba="0.901961 0.772549 0.694118 1.000000"/>
            </material>
        </visual>
        <visual>
            <origin xyz="0.000000 0.000000 0.000000" rpy="0.000000 0.000000 0.000000"/>
            <geometry>
                <mesh filename="package://human_model/meshes/pelvis-polyhedre2.dae"/>
            </geometry>
            <material name="pelvis_polyhedre2">
                <color rgba="0.992157 0.466667 0.466667 1.000000"/>
            </material>
        </visual>
        <visual>
            <origin xyz="0.000000 0.000000 0.000000" rpy="0.000000 0.000000 0.000000"/>
            <geometry>
                <mesh filename="package://human_model/meshes/pelvis-polyhedre3.dae"/>
            </geometry>
            <material name="pelvis_polyhedre3">
                <color rgba="0.190401 0.311497 0.805370 1.000000"/>
            </material>
        </visual>
        <visual>
            <origin xyz="0.000000 0.000000 0.000000" rpy="0.000000 0.000000 0.000000"/>
            <geometry>
                <mesh filename="package://human_model/meshes/pelvis-polyhedre4.dae"/>
            </geometry>
            <material name="pelvis_polyhedre4">
                <color rgba="0.323049 0.186374 0.136675 1.000000"/>
            </material>
        </visual>
        <visual>
            <origin xyz="0.000000 0.000000 0.000000" rpy="0.000000 0.000000 0.000000"/>
            <geometry>
                <mesh filename="package://human_model/meshes/pelvis-polyhedre5.dae"/>
            </geometry>
            <material name="pelvis_polyhedre5">
                <color rgba="0.062745 0.545098 0.796078 1.000000"/>
            </material>
        </visual>
        <visual>
            <origin xyz="0.000000 0.000000 0.000000" rpy="0.000000 0.000000 0.000000"/>
            <geometry>
                <mesh filename="package://human_model/meshes/pelvis-polyhedre6.dae"/>
            </geometry>
            <material name="pelvis_polyhedre6">
                <color rgba="1.000000 0.882353 0.000000 1.000000"/>
            </material>
        </visual>
    </link>
    <link name="pelvis+TorsoY+TorsoZ">
        <collision>
            <origin xyz="0.027581 -0.003062 -0.037279" rpy="0.000000 0.000000 90.000000"/>
            <geometry>
                <cylinder radius="0.181900" length="0.297400"/>
            </geometry>
        </collision>
        <visual>
            <origin xyz="0.000000 0.000000 0.000000" rpy="0.000000 0.000000 0.000000"/>
            <geometry>
                <mesh filename="package://human_model/meshes/pelvis-polyhedre1.dae"/>
            </geometry>
            <material name="pelvis_polyhedre1">
                <color rgba="0.901961 0.772549 0.694118 1.000000"/>
            </material>
        </visual>
        <visual>
            <origin xyz="0.000000 0.000000 0.000000" rpy="0.000000 0.000000 0.000000"/>
            <geometry>
                <mesh filename="package://human_model/meshes/pelvis-polyhedre2.dae"/>
            </geometry>
            <material name="pelvis_polyhedre2">
                <color rgba="0.992157 0.466667 0.466667 1.000000"/>
            </material>
        </visual>
        <visual>
            <origin xyz="0.000000 0.000000 0.000000" rpy="0.000000 0.000000 0.000000"/>
            <geometry>
                <mesh filename="package://human_model/meshes/pelvis-polyhedre3.dae"/>
            </geometry>
            <material name="pelvis_polyhedre3">
                <color rgba="0.190401 0.311497 0.805370 1.000000"/>
            </material>
        </visual>
        <visual>
            <origin xyz="0.000000 0.000000 0.000000" rpy="0.000000 0.000000 0.000000"/>
            <geometry>
                <mesh filename="package://human_model/meshes/pelvis-polyhedre4.dae"/>
            </geometry>
            <material name="pelvis_polyhedre4">
                <color rgba="0.323049 0.186374 0.136675 1.000000"/>
            </material>
        </visual>
        <visual>
            <origin xyz="0.000000 0.000000 0.000000" rpy="0.000000 0.000000 0.000000"/>
            <geometry>
                <mesh filename="package://human_model/meshes/pelvis-polyhedre5.dae"/>
            </geometry>
            <material name="pelvis_polyhedre5">
                <color rgba="0.062745 0.545098 0.796078 1.000000"/>
            </material>
        </visual>
        <visual>
            <origin xyz="0.000000 0.000000 0.000000" rpy="0.000000 0.000000 0.000000"/>
            <geometry>
                <mesh filename="package://human_model/meshes/pelvis-polyhedre6.dae"/>
            </geometry>
            <material name="pelvis_polyhedre6">
                <color rgba="1.000000 0.882353 0.000000 1.000000"/>
            </material>
        </visual>
    </link>
    <link name="torso">
        <collision>
            <origin xyz="0.026467 -0.002893 0.242837" rpy="0.000000 0.000000 90.000000"/>
            <geometry>
                <cylinder radius="0.203000" length="0.257400"/>
            </geometry>
        </collision>
        <collision>
            <origin xyz="0.010646 -0.004374 0.447362" rpy="0.000000 0.000000 90.000000"/>
            <geometry>
                <box size="0.403100 0.203500 0.151500"/>
            </geometry>
        </collision>
        <collision>
            <origin xyz="0.013842 -0.004374 0.540227" rpy="0.000000 0.000000 90.000000"/>
            <geometry>
                <cylinder radius="0.073700" length="0.126700"/>
            </geometry>
        </collision>
        <visual>
            <origin xyz="0.000000 0.000000 0.000000" rpy="0.000000 0.000000 0.000000"/>
            <geometry>
                <mesh filename="package://human_model/meshes/torso-polyhedre1.dae"/>
            </geometry>
            <material name="torso_polyhedre1">
                <color rgba="0.901961 0.772549 0.694118 1.000000"/>
            </material>
        </visual>
        <visual>
            <origin xyz="0.000000 0.000000 0.000000" rpy="0.000000 0.000000 0.000000"/>
            <geometry>
                <mesh filename="package://human_model/meshes/torso-polyhedre2.dae"/>
            </geometry>
            <material name="torso_polyhedre2">
                <color rgba="0.992157 0.466667 0.466667 1.000000"/>
            </material>
        </visual>
        <visual>
            <origin xyz="0.000000 0.000000 0.000000" rpy="0.000000 0.000000 0.000000"/>
            <geometry>
                <mesh filename="package://human_model/meshes/torso-polyhedre3.dae"/>
            </geometry>
            <material name="torso_polyhedre3">
                <color rgba="0.062745 0.545098 0.796078 1.000000"/>
            </material>
        </visual>
        <visual>
            <origin xyz="0.000000 0.000000 0.000000" rpy="0.000000 0.000000 0.000000"/>
            <geometry>
                <mesh filename="package://human_model/meshes/torso-polyhedre4.dae"/>
            </geometry>
            <material name="torso_polyhedre4">
                <color rgba="1.000000 0.882353 0.000000 1.000000"/>
            </material>
        </visual>
        <visual>
            <origin xyz="0.000000 0.000000 0.000000" rpy="0.000000 0.000000 0.000000"/>
            <geometry>
                <mesh filename="package://human_model/meshes/torso-polyhedre5.dae"/>
            </geometry>
            <material name="torso_polyhedre5">
                <color rgba="0.752941 0.752941 0.752941 1.000000"/>
            </material>
        </visual>
        <visual>
            <origin xyz="0.000000 0.000000 0.000000" rpy="0.000000 0.000000 0.000000"/>
            <geometry>
                <mesh filename="package://human_model/meshes/torso-polyhedre6.dae"/>
            </geometry>
            <material name="torso_polyhedre6">
                <color rgba="0.992484 0.466773 0.466773 1.000000"/>
            </material>
        </visual>
    </link>
    <link name="torso+HeadY">
        <collision>
            <origin xyz="0.026467 -0.002893 0.242837" rpy="0.000000 0.000000 90.000000"/>
            <geometry>
                <cylinder radius="0.203000" length="0.257400"/>
            </geometry>
        </collision>
        <collision>
            <origin xyz="0.010646 -0.004374 0.447362" rpy="0.000000 0.000000 90.000000"/>
            <geometry>
                <box size="0.403100 0.203500 0.151500"/>
            </geometry>
        </collision>
        <collision>
            <origin xyz="0.013842 -0.004374 0.540227" rpy="0.000000 0.000000 90.000000"/>
            <geometry>
                <cylinder radius="0.073700" length="0.126700"/>
            </geometry>
        </collision>
        <visual>
            <origin xyz="0.000000 0.000000 0.000000" rpy="0.000000 0.000000 0.000000"/>
            <geometry>
                <mesh filename="package://human_model/meshes/torso-polyhedre1.dae"/>
            </geometry>
            <material name="torso_polyhedre1">
                <color rgba="0.901961 0.772549 0.694118 1.000000"/>
            </material>
        </visual>
        <visual>
            <origin xyz="0.000000 0.000000 0.000000" rpy="0.000000 0.000000 0.000000"/>
            <geometry>
                <mesh filename="package://human_model/meshes/torso-polyhedre2.dae"/>
            </geometry>
            <material name="torso_polyhedre2">
                <color rgba="0.992157 0.466667 0.466667 1.000000"/>
            </material>
        </visual>
        <visual>
            <origin xyz="0.000000 0.000000 0.000000" rpy="0.000000 0.000000 0.000000"/>
            <geometry>
                <mesh filename="package://human_model/meshes/torso-polyhedre3.dae"/>
            </geometry>
            <material name="torso_polyhedre3">
                <color rgba="0.062745 0.545098 0.796078 1.000000"/>
            </material>
        </visual>
        <visual>
            <origin xyz="0.000000 0.000000 0.000000" rpy="0.000000 0.000000 0.000000"/>
            <geometry>
                <mesh filename="package://human_model/meshes/torso-polyhedre4.dae"/>
            </geometry>
            <material name="torso_polyhedre4">
                <color rgba="1.000000 0.882353 0.000000 1.000000"/>
            </material>
        </visual>
        <visual>
            <origin xyz="0.000000 0.000000 0.000000" rpy="0.000000 0.000000 0.000000"/>
            <geometry>
                <mesh filename="package://human_model/meshes/torso-polyhedre5.dae"/>
            </geometry>
            <material name="torso_polyhedre5">
                <color rgba="0.752941 0.752941 0.752941 1.000000"/>
            </material>
        </visual>
        <visual>
            <origin xyz="0.000000 0.000000 0.000000" rpy="0.000000 0.000000 0.000000"/>
            <geometry>
                <mesh filename="package://human_model/meshes/torso-polyhedre6.dae"/>
            </geometry>
            <material name="torso_polyhedre6">
                <color rgba="0.992484 0.466773 0.466773 1.000000"/>
            </material>
        </visual>
    </link>
    <link name="head">
        <collision>
            <origin xyz="0.057591 -0.004925 0.682654" rpy="0.000000 0.000000 90.000000"/>
            <geometry>
                <cylinder radius="0.118400" length="0.256200"/>
            </geometry>
        </collision>
        <visual>
            <origin xyz="0.000000 0.000000 0.000000" rpy="0.000000 0.000000 0.000000"/>
            <geometry>
                <mesh filename="package://human_model/meshes/head-polyhedre1.dae"/>
            </geometry>
            <material name="head_polyhedre1">
                <color rgba="0.901961 0.772549 0.694118 1.000000"/>
            </material>
        </visual>
        <visual>
            <origin xyz="0.000000 0.000000 0.000000" rpy="0.000000 0.000000 0.000000"/>
            <geometry>
                <mesh filename="package://human_model/meshes/head-polyhedre2.dae"/>
            </geometry>
            <material name="head_polyhedre2">
                <color rgba="0.000000 0.000000 0.000000 1.000000"/>
            </material>
        </visual>
        <visual>
            <origin xyz="0.000000 0.000000 0.000000" rpy="0.000000 0.000000 0.000000"/>
            <geometry>
                <mesh filename="package://human_model/meshes/head-polyhedre3.dae"/>
            </geometry>
            <material name="head_polyhedre3">
                <color rgba="0.901961 0.772549 0.694118 1.000000"/>
            </material>
        </visual>
        <visual>
            <origin xyz="0.000000 0.000000 0.000000" rpy="0.000000 0.000000 0.000000"/>
            <geometry>
                <mesh filename="package://human_model/meshes/head-polyhedre4.dae"/>
            </geometry>
            <material name="head_polyhedre4">
                <color rgba="1.000000 1.000000 1.000000 1.000000"/>
            </material>
        </visual>
        <visual>
            <origin xyz="0.000000 0.000000 0.000000" rpy="0.000000 0.000000 0.000000"/>
            <geometry>
                <mesh filename="package://human_model/meshes/head-polyhedre5.dae"/>
            </geometry>
            <material name="head_polyhedre5">
                <color rgba="0.000000 0.000000 0.000000 1.000000"/>
            </material>
        </visual>
        <visual>
            <origin xyz="0.000000 0.000000 0.000000" rpy="0.000000 0.000000 0.000000"/>
            <geometry>
                <mesh filename="package://human_model/meshes/head-polyhedre6.dae"/>
            </geometry>
            <material name="head_polyhedre6">
                <color rgba="0.000000 0.000000 0.000000 1.000000"/>
            </material>
        </visual>
    </link>
    <link name="torso+rShoulderZ">
        <collision>
            <origin xyz="0.026467 -0.002893 0.242837" rpy="0.000000 0.000000 90.000000"/>
            <geometry>
                <cylinder radius="0.203000" length="0.257400"/>
            </geometry>
        </collision>
        <collision>
            <origin xyz="0.010646 -0.004374 0.447362" rpy="0.000000 0.000000 90.000000"/>
            <geometry>
                <box size="0.403100 0.203500 0.151500"/>
            </geometry>
        </collision>
        <collision>
            <origin xyz="0.013842 -0.004374 0.540227" rpy="0.000000 0.000000 90.000000"/>
            <geometry>
                <cylinder radius="0.073700" length="0.126700"/>
            </geometry>
        </collision>
        <visual>
            <origin xyz="0.000000 0.000000 0.000000" rpy="0.000000 0.000000 0.000000"/>
            <geometry>
                <mesh filename="package://human_model/meshes/torso-polyhedre1.dae"/>
            </geometry>
            <material name="torso_polyhedre1">
                <color rgba="0.901961 0.772549 0.694118 1.000000"/>
            </material>
        </visual>
        <visual>
            <origin xyz="0.000000 0.000000 0.000000" rpy="0.000000 0.000000 0.000000"/>
            <geometry>
                <mesh filename="package://human_model/meshes/torso-polyhedre2.dae"/>
            </geometry>
            <material name="torso_polyhedre2">
                <color rgba="0.992157 0.466667 0.466667 1.000000"/>
            </material>
        </visual>
        <visual>
            <origin xyz="0.000000 0.000000 0.000000" rpy="0.000000 0.000000 0.000000"/>
            <geometry>
                <mesh filename="package://human_model/meshes/torso-polyhedre3.dae"/>
            </geometry>
            <material name="torso_polyhedre3">
                <color rgba="0.062745 0.545098 0.796078 1.000000"/>
            </material>
        </visual>
        <visual>
            <origin xyz="0.000000 0.000000 0.000000" rpy="0.000000 0.000000 0.000000"/>
            <geometry>
                <mesh filename="package://human_model/meshes/torso-polyhedre4.dae"/>
            </geometry>
            <material name="torso_polyhedre4">
                <color rgba="1.000000 0.882353 0.000000 1.000000"/>
            </material>
        </visual>
        <visual>
            <origin xyz="0.000000 0.000000 0.000000" rpy="0.000000 0.000000 0.000000"/>
            <geometry>
                <mesh filename="package://human_model/meshes/torso-polyhedre5.dae"/>
            </geometry>
            <material name="torso_polyhedre5">
                <color rgba="0.752941 0.752941 0.752941 1.000000"/>
            </material>
        </visual>
        <visual>
            <origin xyz="0.000000 0.000000 0.000000" rpy="0.000000 0.000000 0.000000"/>
            <geometry>
                <mesh filename="package://human_model/meshes/torso-polyhedre6.dae"/>
            </geometry>
            <material name="torso_polyhedre6">
                <color rgba="0.992484 0.466773 0.466773 1.000000"/>
            </material>
        </visual>
    </link>
    <link name="torso+rShoulderZ+rShoulderY">
        <collision>
            <origin xyz="0.026467 -0.002893 0.242837" rpy="0.000000 0.000000 90.000000"/>
            <geometry>
                <cylinder radius="0.203000" length="0.257400"/>
            </geometry>
        </collision>
        <collision>
            <origin xyz="0.010646 -0.004374 0.447362" rpy="0.000000 0.000000 90.000000"/>
            <geometry>
                <box size="0.403100 0.203500 0.151500"/>
            </geometry>
        </collision>
        <collision>
            <origin xyz="0.013842 -0.004374 0.540227" rpy="0.000000 0.000000 90.000000"/>
            <geometry>
                <cylinder radius="0.073700" length="0.126700"/>
            </geometry>
        </collision>
        <visual>
            <origin xyz="0.000000 0.000000 0.000000" rpy="0.000000 0.000000 0.000000"/>
            <geometry>
                <mesh filename="package://human_model/meshes/torso-polyhedre1.dae"/>
            </geometry>
            <material name="torso_polyhedre1">
                <color rgba="0.901961 0.772549 0.694118 1.000000"/>
            </material>
        </visual>
        <visual>
            <origin xyz="0.000000 0.000000 0.000000" rpy="0.000000 0.000000 0.000000"/>
            <geometry>
                <mesh filename="package://human_model/meshes/torso-polyhedre2.dae"/>
            </geometry>
            <material name="torso_polyhedre2">
                <color rgba="0.992157 0.466667 0.466667 1.000000"/>
            </material>
        </visual>
        <visual>
            <origin xyz="0.000000 0.000000 0.000000" rpy="0.000000 0.000000 0.000000"/>
            <geometry>
                <mesh filename="package://human_model/meshes/torso-polyhedre3.dae"/>
            </geometry>
            <material name="torso_polyhedre3">
                <color rgba="0.062745 0.545098 0.796078 1.000000"/>
            </material>
        </visual>
        <visual>
            <origin xyz="0.000000 0.000000 0.000000" rpy="0.000000 0.000000 0.000000"/>
            <geometry>
                <mesh filename="package://human_model/meshes/torso-polyhedre4.dae"/>
            </geometry>
            <material name="torso_polyhedre4">
                <color rgba="1.000000 0.882353 0.000000 1.000000"/>
            </material>
        </visual>
        <visual>
            <origin xyz="0.000000 0.000000 0.000000" rpy="0.000000 0.000000 0.000000"/>
            <geometry>
                <mesh filename="package://human_model/meshes/torso-polyhedre5.dae"/>
            </geometry>
            <material name="torso_polyhedre5">
                <color rgba="0.752941 0.752941 0.752941 1.000000"/>
            </material>
        </visual>
        <visual>
            <origin xyz="0.000000 0.000000 0.000000" rpy="0.000000 0.000000 0.000000"/>
            <geometry>
                <mesh filename="package://human_model/meshes/torso-polyhedre6.dae"/>
            </geometry>
            <material name="torso_polyhedre6">
                <color rgba="0.992484 0.466773 0.466773 1.000000"/>
            </material>
        </visual>
    </link>
    <link name="rHumerus">
        <collision>
            <origin xyz="-0.007111 -0.326332 0.437434" rpy="0.000000 -92.800000 90.000000"/>
            <geometry>
                <cylinder radius="0.067450" length="0.247500"/>
            </geometry>
        </collision>
        <visual>
            <origin xyz="0.000000 0.000000 0.000000" rpy="0.000000 0.000000 0.000000"/>
            <geometry>
                <mesh filename="package://human_model/meshes/rHumerus-polyhedre1.dae"/>
            </geometry>
            <material name="rHumerus_polyhedre1">
                <color rgba="0.901961 0.772549 0.694118 1.000000"/>
            </material>
        </visual>
        <visual>
            <origin xyz="0.000000 0.000000 0.000000" rpy="0.000000 0.000000 0.000000"/>
            <geometry>
                <mesh filename="package://human_model/meshes/rHumerus-polyhedre2.dae"/>
            </geometry>
            <material name="rHumerus_polyhedre2">
                <color rgba="0.992157 0.466667 0.466667 1.000000"/>
            </material>
        </visual>
    </link>
    <link name="rHumerus+rElbowZ">
        <collision>
            <origin xyz="-0.007111 -0.326332 0.437434" rpy="0.000000 -92.800000 90.000000"/>
            <geometry>
                <cylinder radius="0.067450" length="0.247500"/>
            </geometry>
        </collision>
        <visual>
            <origin xyz="0.000000 0.000000 0.000000" rpy="0.000000 0.000000 0.000000"/>
            <geometry>
                <mesh filename="package://human_model/meshes/rHumerus-polyhedre1.dae"/>
            </geometry>
            <material name="rHumerus_polyhedre1">
                <color rgba="0.901961 0.772549 0.694118 1.000000"/>
            </material>
        </visual>
        <visual>
            <origin xyz="0.000000 0.000000 0.000000" rpy="0.000000 0.000000 0.000000"/>
            <geometry>
                <mesh filename="package://human_model/meshes/rHumerus-polyhedre2.dae"/>
            </geometry>
            <material name="rHumerus_polyhedre2">
                <color rgba="0.992157 0.466667 0.466667 1.000000"/>
            </material>
        </visual>
    </link>
    <link name="rRadius">
        <collision>
            <origin xyz="0.003544 -0.581679 0.432170" rpy="0.000000 -87.500000 90.000000"/>
            <geometry>
                <cylinder radius="0.053000" length="0.281400"/>
            </geometry>
        </collision>
        <visual>
            <origin xyz="0.000000 0.000000 0.000000" rpy="0.000000 0.000000 0.000000"/>
            <geometry>
                <mesh filename="package://human_model/meshes/rRadius-polyhedre1.dae"/>
            </geometry>
            <material name="rRadius_polyhedre1">
                <color rgba="0.901961 0.772549 0.694118 1.000000"/>
            </material>
        </visual>
    </link>
    <link name="rRadius+rWristX">
        <collision>
            <origin xyz="0.003544 -0.581679 0.432170" rpy="0.000000 -87.500000 90.000000"/>
            <geometry>
                <cylinder radius="0.053000" length="0.281400"/>
            </geometry>
        </collision>
        <visual>
            <origin xyz="0.000000 0.000000 0.000000" rpy="0.000000 0.000000 0.000000"/>
            <geometry>
                <mesh filename="package://human_model/meshes/rRadius-polyhedre1.dae"/>
            </geometry>
            <material name="rRadius_polyhedre1">
                <color rgba="0.901961 0.772549 0.694118 1.000000"/>
            </material>
        </visual>
    </link>
    <link name="rRadius+rWristX+rWristY">
        <collision>
            <origin xyz="0.003544 -0.581679 0.432170" rpy="0.000000 -87.500000 90.000000"/>
            <geometry>
                <cylinder radius="0.053000" length="0.281400"/>
            </geometry>
        </collision>
        <visual>
            <origin xyz="0.000000 0.000000 0.000000" rpy="0.000000 0.000000 0.000000"/>
            <geometry>
                <mesh filename="package://human_model/meshes/rRadius-polyhedre1.dae"/>
            </geometry>
            <material name="rRadius_polyhedre1">
                <color rgba="0.901961 0.772549 0.694118 1.000000"/>
            </material>
        </visual>
    </link>
    <link name="rRadius+rWristX+rWristY+rWristZ">
        <collision>
            <origin xyz="0.003544 -0.581679 0.432170" rpy="0.000000 -87.500000 90.000000"/>
            <geometry>
                <cylinder radius="0.053000" length="0.281400"/>
            </geometry>
        </collision>
        <visual>
            <origin xyz="0.000000 0.000000 0.000000" rpy="0.000000 0.000000 0.000000"/>
            <geometry>
                <mesh filename="package://human_model/meshes/rRadius-polyhedre1.dae"/>
            </geometry>
            <material name="rRadius_polyhedre1">
                <color rgba="0.901961 0.772549 0.694118 1.000000"/>
            </material>
        </visual>
    </link>
    <link name="rHand">
        <collision>
            <origin xyz="0.001872 -0.759930 0.447190" rpy="0.000000 18.900000 90.000000"/>
            <geometry>
                <box size="0.137600 0.096000 0.055000"/>
            </geometry>
        </collision>
        <collision>
            <origin xyz="0.001872 -0.864078 0.472072" rpy="0.000000 0.000000 90.000000"/>
            <geometry>
                <box size="0.090300 0.098700 0.030400"/>
            </geometry>
        </collision>
        <collision>
            <origin xyz="0.063221 -0.789444 0.437595" rpy="0.000000 0.000000 106.600000"/>
            <geometry>
                <box size="0.089400 0.024800 0.031200"/>
            </geometry>
        </collision>
        <visual>
            <origin xyz="0.000000 0.000000 0.000000" rpy="0.000000 0.000000 0.000000"/>
            <geometry>
                <mesh filename="package://human_model/meshes/rHand-polyhedre1.dae"/>
            </geometry>
            <material name="rHand_polyhedre1">
                <color rgba="0.901961 0.772549 0.694118 1.000000"/>
            </material>
        </visual>
    </link>
    <link name="torso+lShoulderZ">
        <collision>
            <origin xyz="0.026467 -0.002893 0.242837" rpy="0.000000 0.000000 90.000000"/>
            <geometry>
                <cylinder radius="0.203000" length="0.257400"/>
            </geometry>
        </collision>
        <collision>
            <origin xyz="0.010646 -0.004374 0.447362" rpy="0.000000 0.000000 90.000000"/>
            <geometry>
                <box size="0.403100 0.203500 0.151500"/>
            </geometry>
        </collision>
        <collision>
            <origin xyz="0.013842 -0.004374 0.540227" rpy="0.000000 0.000000 90.000000"/>
            <geometry>
                <cylinder radius="0.073700" length="0.126700"/>
            </geometry>
        </collision>
        <visual>
            <origin xyz="0.000000 0.000000 0.000000" rpy="0.000000 0.000000 0.000000"/>
            <geometry>
                <mesh filename="package://human_model/meshes/torso-polyhedre1.dae"/>
            </geometry>
            <material name="torso_polyhedre1">
                <color rgba="0.901961 0.772549 0.694118 1.000000"/>
            </material>
        </visual>
        <visual>
            <origin xyz="0.000000 0.000000 0.000000" rpy="0.000000 0.000000 0.000000"/>
            <geometry>
                <mesh filename="package://human_model/meshes/torso-polyhedre2.dae"/>
            </geometry>
            <material name="torso_polyhedre2">
                <color rgba="0.992157 0.466667 0.466667 1.000000"/>
            </material>
        </visual>
        <visual>
            <origin xyz="0.000000 0.000000 0.000000" rpy="0.000000 0.000000 0.000000"/>
            <geometry>
                <mesh filename="package://human_model/meshes/torso-polyhedre3.dae"/>
            </geometry>
            <material name="torso_polyhedre3">
                <color rgba="0.062745 0.545098 0.796078 1.000000"/>
            </material>
        </visual>
        <visual>
            <origin xyz="0.000000 0.000000 0.000000" rpy="0.000000 0.000000 0.000000"/>
            <geometry>
                <mesh filename="package://human_model/meshes/torso-polyhedre4.dae"/>
            </geometry>
            <material name="torso_polyhedre4">
                <color rgba="1.000000 0.882353 0.000000 1.000000"/>
            </material>
        </visual>
        <visual>
            <origin xyz="0.000000 0.000000 0.000000" rpy="0.000000 0.000000 0.000000"/>
            <geometry>
                <mesh filename="package://human_model/meshes/torso-polyhedre5.dae"/>
            </geometry>
            <material name="torso_polyhedre5">
                <color rgba="0.752941 0.752941 0.752941 1.000000"/>
            </material>
        </visual>
        <visual>
            <origin xyz="0.000000 0.000000 0.000000" rpy="0.000000 0.000000 0.000000"/>
            <geometry>
                <mesh filename="package://human_model/meshes/torso-polyhedre6.dae"/>
            </geometry>
            <material name="torso_polyhedre6">
                <color rgba="0.992484 0.466773 0.466773 1.000000"/>
            </material>
        </visual>
    </link>
    <link name="torso+lShoulderZ+lShoulderY">
        <collision>
            <origin xyz="0.026467 -0.002893 0.242837" rpy="0.000000 0.000000 90.000000"/>
            <geometry>
                <cylinder radius="0.203000" length="0.257400"/>
            </geometry>
        </collision>
        <collision>
            <origin xyz="0.010646 -0.004374 0.447362" rpy="0.000000 0.000000 90.000000"/>
            <geometry>
                <box size="0.403100 0.203500 0.151500"/>
            </geometry>
        </collision>
        <collision>
            <origin xyz="0.013842 -0.004374 0.540227" rpy="0.000000 0.000000 90.000000"/>
            <geometry>
                <cylinder radius="0.073700" length="0.126700"/>
            </geometry>
        </collision>
        <visual>
            <origin xyz="0.000000 0.000000 0.000000" rpy="0.000000 0.000000 0.000000"/>
            <geometry>
                <mesh filename="package://human_model/meshes/torso-polyhedre1.dae"/>
            </geometry>
            <material name="torso_polyhedre1">
                <color rgba="0.901961 0.772549 0.694118 1.000000"/>
            </material>
        </visual>
        <visual>
            <origin xyz="0.000000 0.000000 0.000000" rpy="0.000000 0.000000 0.000000"/>
            <geometry>
                <mesh filename="package://human_model/meshes/torso-polyhedre2.dae"/>
            </geometry>
            <material name="torso_polyhedre2">
                <color rgba="0.992157 0.466667 0.466667 1.000000"/>
            </material>
        </visual>
        <visual>
            <origin xyz="0.000000 0.000000 0.000000" rpy="0.000000 0.000000 0.000000"/>
            <geometry>
                <mesh filename="package://human_model/meshes/torso-polyhedre3.dae"/>
            </geometry>
            <material name="torso_polyhedre3">
                <color rgba="0.062745 0.545098 0.796078 1.000000"/>
            </material>
        </visual>
        <visual>
            <origin xyz="0.000000 0.000000 0.000000" rpy="0.000000 0.000000 0.000000"/>
            <geometry>
                <mesh filename="package://human_model/meshes/torso-polyhedre4.dae"/>
            </geometry>
            <material name="torso_polyhedre4">
                <color rgba="1.000000 0.882353 0.000000 1.000000"/>
            </material>
        </visual>
        <visual>
            <origin xyz="0.000000 0.000000 0.000000" rpy="0.000000 0.000000 0.000000"/>
            <geometry>
                <mesh filename="package://human_model/meshes/torso-polyhedre5.dae"/>
            </geometry>
            <material name="torso_polyhedre5">
                <color rgba="0.752941 0.752941 0.752941 1.000000"/>
            </material>
        </visual>
        <visual>
            <origin xyz="0.000000 0.000000 0.000000" rpy="0.000000 0.000000 0.000000"/>
            <geometry>
                <mesh filename="package://human_model/meshes/torso-polyhedre6.dae"/>
            </geometry>
            <material name="torso_polyhedre6">
                <color rgba="0.992484 0.466773 0.466773 1.000000"/>
            </material>
        </visual>
    </link>
    <link name="lHumerus">
        <collision>
            <origin xyz="-0.007111 0.319938 0.432528" rpy="0.000000 92.800000 90.000000"/>
            <geometry>
                <cylinder radius="0.067450" length="0.247500"/>
            </geometry>
        </collision>
        <visual>
            <origin xyz="0.000000 0.000000 0.000000" rpy="0.000000 0.000000 0.000000"/>
            <geometry>
                <mesh filename="package://human_model/meshes/lHumerus-polyhedre1.dae"/>
            </geometry>
            <material name="lHumerus_polyhedre1">
                <color rgba="0.901961 0.772549 0.694118 1.000000"/>
            </material>
        </visual>
        <visual>
            <origin xyz="0.000000 0.000000 0.000000" rpy="0.000000 0.000000 0.000000"/>
            <geometry>
                <mesh filename="package://human_model/meshes/lHumerus-polyhedre2.dae"/>
            </geometry>
            <material name="lHumerus_polyhedre2">
                <color rgba="0.992157 0.466667 0.466667 1.000000"/>
            </material>
        </visual>
    </link>
    <link name="lHumerus+lElbowZ">
        <collision>
            <origin xyz="-0.007111 0.319938 0.432528" rpy="0.000000 92.800000 90.000000"/>
            <geometry>
                <cylinder radius="0.067450" length="0.247500"/>
            </geometry>
        </collision>
        <visual>
            <origin xyz="0.000000 0.000000 0.000000" rpy="0.000000 0.000000 0.000000"/>
            <geometry>
                <mesh filename="package://human_model/meshes/lHumerus-polyhedre1.dae"/>
            </geometry>
            <material name="lHumerus_polyhedre1">
                <color rgba="0.901961 0.772549 0.694118 1.000000"/>
            </material>
        </visual>
        <visual>
            <origin xyz="0.000000 0.000000 0.000000" rpy="0.000000 0.000000 0.000000"/>
            <geometry>
                <mesh filename="package://human_model/meshes/lHumerus-polyhedre2.dae"/>
            </geometry>
            <material name="lHumerus_polyhedre2">
                <color rgba="0.992157 0.466667 0.466667 1.000000"/>
            </material>
        </visual>
    </link>
    <link name="lRadius">
        <collision>
            <origin xyz="0.003544 0.575555 0.432170" rpy="0.000000 87.500000 90.000000"/>
            <geometry>
                <cylinder radius="0.053000" length="0.281400"/>
            </geometry>
        </collision>
        <visual>
            <origin xyz="0.000000 0.000000 0.000000" rpy="0.000000 0.000000 0.000000"/>
            <geometry>
                <mesh filename="package://human_model/meshes/lRadius-polyhedre1.dae"/>
            </geometry>
            <material name="lRadius_polyhedre1">
                <color rgba="0.901961 0.772549 0.694118 1.000000"/>
            </material>
        </visual>
    </link>
    <link name="lRadius+lWristX">
        <collision>
            <origin xyz="0.003544 0.575555 0.432170" rpy="0.000000 87.500000 90.000000"/>
            <geometry>
                <cylinder radius="0.053000" length="0.281400"/>
            </geometry>
        </collision>
        <visual>
            <origin xyz="0.000000 0.000000 0.000000" rpy="0.000000 0.000000 0.000000"/>
            <geometry>
                <mesh filename="package://human_model/meshes/lRadius-polyhedre1.dae"/>
            </geometry>
            <material name="lRadius_polyhedre1">
                <color rgba="0.901961 0.772549 0.694118 1.000000"/>
            </material>
        </visual>
    </link>
    <link name="lRadius+lWristX+lWristY">
        <collision>
            <origin xyz="0.003544 0.575555 0.432170" rpy="0.000000 87.500000 90.000000"/>
            <geometry>
                <cylinder radius="0.053000" length="0.281400"/>
            </geometry>
        </collision>
        <visual>
            <origin xyz="0.000000 0.000000 0.000000" rpy="0.000000 0.000000 0.000000"/>
            <geometry>
                <mesh filename="package://human_model/meshes/lRadius-polyhedre1.dae"/>
            </geometry>
            <material name="lRadius_polyhedre1">
                <color rgba="0.901961 0.772549 0.694118 1.000000"/>
            </material>
        </visual>
    </link>
    <link name="lRadius+lWristX+lWristY+lWristZ">
        <collision>
            <origin xyz="0.003544 0.575555 0.432170" rpy="0.000000 87.500000 90.000000"/>
            <geometry>
                <cylinder radius="0.053000" length="0.281400"/>
            </geometry>
        </collision>
        <visual>
            <origin xyz="0.000000 0.000000 0.000000" rpy="0.000000 0.000000 0.000000"/>
            <geometry>
                <mesh filename="package://human_model/meshes/lRadius-polyhedre1.dae"/>
            </geometry>
            <material name="lRadius_polyhedre1">
                <color rgba="0.901961 0.772549 0.694118 1.000000"/>
            </material>
        </visual>
    </link>
    <link name="lHand">
        <collision>
            <origin xyz="0.001872 0.753806 0.447190" rpy="0.000000 -18.900000 90.000000"/>
            <geometry>
                <box size="0.137600 0.096000 0.055000"/>
            </geometry>
        </collision>
        <collision>
            <origin xyz="0.001872 0.857954 0.472072" rpy="0.000000 0.000000 90.000000"/>
            <geometry>
                <box size="0.090300 0.098700 0.030400"/>
            </geometry>
        </collision>
        <collision>
            <origin xyz="0.063221 0.783320 0.437595" rpy="0.000000 0.000000 -106.600000"/>
            <geometry>
                <box size="0.089400 0.024800 0.031200"/>
            </geometry>
        </collision>
        <visual>
            <origin xyz="0.000000 0.000000 0.000000" rpy="0.000000 0.000000 0.000000"/>
            <geometry>
                <mesh filename="package://human_model/meshes/lHand-polyhedre1.dae"/>
            </geometry>
            <material name="lHand_polyhedre1">
                <color rgba="0.901961 0.772549 0.694118 1.000000"/>
            </material>
        </visual>
    </link>
    <link name="pelvis+rHipY">
        <collision>
            <origin xyz="0.027581 -0.003062 -0.037279" rpy="0.000000 0.000000 90.000000"/>
            <geometry>
                <cylinder radius="0.181900" length="0.297400"/>
            </geometry>
        </collision>
        <visual>
            <origin xyz="0.000000 0.000000 0.000000" rpy="0.000000 0.000000 0.000000"/>
            <geometry>
                <mesh filename="package://human_model/meshes/pelvis-polyhedre1.dae"/>
            </geometry>
            <material name="pelvis_polyhedre1">
                <color rgba="0.901961 0.772549 0.694118 1.000000"/>
            </material>
        </visual>
        <visual>
            <origin xyz="0.000000 0.000000 0.000000" rpy="0.000000 0.000000 0.000000"/>
            <geometry>
                <mesh filename="package://human_model/meshes/pelvis-polyhedre2.dae"/>
            </geometry>
            <material name="pelvis_polyhedre2">
                <color rgba="0.992157 0.466667 0.466667 1.000000"/>
            </material>
        </visual>
        <visual>
            <origin xyz="0.000000 0.000000 0.000000" rpy="0.000000 0.000000 0.000000"/>
            <geometry>
                <mesh filename="package://human_model/meshes/pelvis-polyhedre3.dae"/>
            </geometry>
            <material name="pelvis_polyhedre3">
                <color rgba="0.190401 0.311497 0.805370 1.000000"/>
            </material>
        </visual>
        <visual>
            <origin xyz="0.000000 0.000000 0.000000" rpy="0.000000 0.000000 0.000000"/>
            <geometry>
                <mesh filename="package://human_model/meshes/pelvis-polyhedre4.dae"/>
            </geometry>
            <material name="pelvis_polyhedre4">
                <color rgba="0.323049 0.186374 0.136675 1.000000"/>
            </material>
        </visual>
        <visual>
            <origin xyz="0.000000 0.000000 0.000000" rpy="0.000000 0.000000 0.000000"/>
            <geometry>
                <mesh filename="package://human_model/meshes/pelvis-polyhedre5.dae"/>
            </geometry>
            <material name="pelvis_polyhedre5">
                <color rgba="0.062745 0.545098 0.796078 1.000000"/>
            </material>
        </visual>
        <visual>
            <origin xyz="0.000000 0.000000 0.000000" rpy="0.000000 0.000000 0.000000"/>
            <geometry>
                <mesh filename="package://human_model/meshes/pelvis-polyhedre6.dae"/>
            </geometry>
            <material name="pelvis_polyhedre6">
                <color rgba="1.000000 0.882353 0.000000 1.000000"/>
            </material>
        </visual>
    </link>
    <link name="pelvis+rHipY+rHipZ">
        <collision>
            <origin xyz="0.027581 -0.003062 -0.037279" rpy="0.000000 0.000000 90.000000"/>
            <geometry>
                <cylinder radius="0.181900" length="0.297400"/>
            </geometry>
        </collision>
        <visual>
            <origin xyz="0.000000 0.000000 0.000000" rpy="0.000000 0.000000 0.000000"/>
            <geometry>
                <mesh filename="package://human_model/meshes/pelvis-polyhedre1.dae"/>
            </geometry>
            <material name="pelvis_polyhedre1">
                <color rgba="0.901961 0.772549 0.694118 1.000000"/>
            </material>
        </visual>
        <visual>
            <origin xyz="0.000000 0.000000 0.000000" rpy="0.000000 0.000000 0.000000"/>
            <geometry>
                <mesh filename="package://human_model/meshes/pelvis-polyhedre2.dae"/>
            </geometry>
            <material name="pelvis_polyhedre2">
                <color rgba="0.992157 0.466667 0.466667 1.000000"/>
            </material>
        </visual>
        <visual>
            <origin xyz="0.000000 0.000000 0.000000" rpy="0.000000 0.000000 0.000000"/>
            <geometry>
                <mesh filename="package://human_model/meshes/pelvis-polyhedre3.dae"/>
            </geometry>
            <material name="pelvis_polyhedre3">
                <color rgba="0.190401 0.311497 0.805370 1.000000"/>
            </material>
        </visual>
        <visual>
            <origin xyz="0.000000 0.000000 0.000000" rpy="0.000000 0.000000 0.000000"/>
            <geometry>
                <mesh filename="package://human_model/meshes/pelvis-polyhedre4.dae"/>
            </geometry>
            <material name="pelvis_polyhedre4">
                <color rgba="0.323049 0.186374 0.136675 1.000000"/>
            </material>
        </visual>
        <visual>
            <origin xyz="0.000000 0.000000 0.000000" rpy="0.000000 0.000000 0.000000"/>
            <geometry>
                <mesh filename="package://human_model/meshes/pelvis-polyhedre5.dae"/>
            </geometry>
            <material name="pelvis_polyhedre5">
                <color rgba="0.062745 0.545098 0.796078 1.000000"/>
            </material>
        </visual>
        <visual>
            <origin xyz="0.000000 0.000000 0.000000" rpy="0.000000 0.000000 0.000000"/>
            <geometry>
                <mesh filename="package://human_model/meshes/pelvis-polyhedre6.dae"/>
            </geometry>
            <material name="pelvis_polyhedre6">
                <color rgba="1.000000 0.882353 0.000000 1.000000"/>
            </material>
        </visual>
    </link>
    <link name="rFemur">
        <collision>
            <origin xyz="0.024098 -0.107529 -0.282207" rpy="0.000000 0.000000 90.000000"/>
            <geometry>
                <cylinder radius="0.100000" length="0.186700"/>
            </geometry>
        </collision>
        <collision>
            <origin xyz="0.010046 -0.098554 -0.476062" rpy="5.200000 0.000000 90.000000"/>
            <geometry>
                <cylinder radius="0.089000" length="0.214900"/>
            </geometry>
        </collision>
        <visual>
            <origin xyz="0.000000 0.000000 0.000000" rpy="0.000000 0.000000 0.000000"/>
            <geometry>
                <mesh filename="package://human_model/meshes/rFemur-polyhedre1.dae"/>
            </geometry>
            <material name="rFemur_polyhedre1">
                <color rgba="0.190000 0.311000 0.805000 1.000000"/>
            </material>
        </visual>
    </link>
    <link name="rTibia">
        <collision>
            <origin xyz="-0.013396 -0.103904 -0.759714" rpy="0.000000 0.000000 90.000000"/>
            <geometry>
                <cylinder radius="0.081700" length="0.349800"/>
            </geometry>
        </collision>
        <visual>
            <origin xyz="0.000000 0.000000 0.000000" rpy="0.000000 0.000000 0.000000"/>
            <geometry>
                <mesh filename="package://human_model/meshes/rTibia-polyhedre1.dae"/>
            </geometry>
            <material name="rTibia_polyhedre1">
                <color rgba="0.188235 0.309804 0.803922 1.000000"/>
            </material>
        </visual>
    </link>
    <link name="rTibia+rAnkleY">
        <collision>
            <origin xyz="-0.013396 -0.103904 -0.759714" rpy="0.000000 0.000000 90.000000"/>
            <geometry>
                <cylinder radius="0.081700" length="0.349800"/>
            </geometry>
        </collision>
        <visual>
            <origin xyz="0.000000 0.000000 0.000000" rpy="0.000000 0.000000 0.000000"/>
            <geometry>
                <mesh filename="package://human_model/meshes/rTibia-polyhedre1.dae"/>
            </geometry>
            <material name="rTibia_polyhedre1">
                <color rgba="0.188235 0.309804 0.803922 1.000000"/>
            </material>
        </visual>
    </link>
    <link name="rTibia+rAnkleY+rAnkleZ">
        <collision>
            <origin xyz="-0.013396 -0.103904 -0.759714" rpy="0.000000 0.000000 90.000000"/>
            <geometry>
                <cylinder radius="0.081700" length="0.349800"/>
            </geometry>
        </collision>
        <visual>
            <origin xyz="0.000000 0.000000 0.000000" rpy="0.000000 0.000000 0.000000"/>
            <geometry>
                <mesh filename="package://human_model/meshes/rTibia-polyhedre1.dae"/>
            </geometry>
            <material name="rTibia_polyhedre1">
                <color rgba="0.188235 0.309804 0.803922 1.000000"/>
            </material>
        </visual>
    </link>
    <link name="rFoot">
        <collision>
            <origin xyz="0.063501 -0.100377 -0.992633" rpy="0.000000 0.000000 90.000000"/>
            <geometry>
                <box size="0.148800 0.328600 0.126100"/>
            </geometry>
        </collision>
        <visual>
            <origin xyz="0.000000 0.000000 0.000000" rpy="0.000000 0.000000 0.000000"/>
            <geometry>
                <mesh filename="package://human_model/meshes/rFoot-polyhedre1.dae"/>
            </geometry>
            <material name="rFoot_polyhedre1">
                <color rgba="1.000000 1.000000 1.000000 1.000000"/>
            </material>
        </visual>
        <visual>
            <origin xyz="0.000000 0.000000 0.000000" rpy="0.000000 0.000000 0.000000"/>
            <geometry>
                <mesh filename="package://human_model/meshes/rFoot-polyhedre2.dae"/>
            </geometry>
            <material name="rFoot_polyhedre2">
                <color rgba="0.619608 0.619608 0.619608 1.000000"/>
            </material>
        </visual>
        <visual>
            <origin xyz="0.000000 0.000000 0.000000" rpy="0.000000 0.000000 0.000000"/>
            <geometry>
                <mesh filename="package://human_model/meshes/rFoot-polyhedre3.dae"/>
            </geometry>
            <material name="rFoot_polyhedre3">
                <color rgba="0.000000 0.000000 0.000000 1.000000"/>
            </material>
        </visual>
        <visual>
            <origin xyz="0.000000 0.000000 0.000000" rpy="0.000000 0.000000 0.000000"/>
            <geometry>
                <mesh filename="package://human_model/meshes/rFoot-polyhedre4.dae"/>
            </geometry>
            <material name="rFoot_polyhedre4">
                <color rgba="0.164706 0.164706 0.447059 1.000000"/>
            </material>
        </visual>
        <visual>
            <origin xyz="0.000000 0.000000 0.000000" rpy="0.000000 0.000000 0.000000"/>
            <geometry>
                <mesh filename="package://human_model/meshes/rFoot-polyhedre5.dae"/>
            </geometry>
            <material name="rFoot_polyhedre5">
                <color rgba="0.568627 0.000000 0.000000 1.000000"/>
            </material>
        </visual>
    </link>
    <link name="pelvis+lHipY">
        <collision>
            <origin xyz="0.027581 -0.003062 -0.037279" rpy="0.000000 0.000000 90.000000"/>
            <geometry>
                <cylinder radius="0.181900" length="0.297400"/>
            </geometry>
        </collision>
        <visual>
            <origin xyz="0.000000 0.000000 0.000000" rpy="0.000000 0.000000 0.000000"/>
            <geometry>
                <mesh filename="package://human_model/meshes/pelvis-polyhedre1.dae"/>
            </geometry>
            <material name="pelvis_polyhedre1">
                <color rgba="0.901961 0.772549 0.694118 1.000000"/>
            </material>
        </visual>
        <visual>
            <origin xyz="0.000000 0.000000 0.000000" rpy="0.000000 0.000000 0.000000"/>
            <geometry>
                <mesh filename="package://human_model/meshes/pelvis-polyhedre2.dae"/>
            </geometry>
            <material name="pelvis_polyhedre2">
                <color rgba="0.992157 0.466667 0.466667 1.000000"/>
            </material>
        </visual>
        <visual>
            <origin xyz="0.000000 0.000000 0.000000" rpy="0.000000 0.000000 0.000000"/>
            <geometry>
                <mesh filename="package://human_model/meshes/pelvis-polyhedre3.dae"/>
            </geometry>
            <material name="pelvis_polyhedre3">
                <color rgba="0.190401 0.311497 0.805370 1.000000"/>
            </material>
        </visual>
        <visual>
            <origin xyz="0.000000 0.000000 0.000000" rpy="0.000000 0.000000 0.000000"/>
            <geometry>
                <mesh filename="package://human_model/meshes/pelvis-polyhedre4.dae"/>
            </geometry>
            <material name="pelvis_polyhedre4">
                <color rgba="0.323049 0.186374 0.136675 1.000000"/>
            </material>
        </visual>
        <visual>
            <origin xyz="0.000000 0.000000 0.000000" rpy="0.000000 0.000000 0.000000"/>
            <geometry>
                <mesh filename="package://human_model/meshes/pelvis-polyhedre5.dae"/>
            </geometry>
            <material name="pelvis_polyhedre5">
                <color rgba="0.062745 0.545098 0.796078 1.000000"/>
            </material>
        </visual>
        <visual>
            <origin xyz="0.000000 0.000000 0.000000" rpy="0.000000 0.000000 0.000000"/>
            <geometry>
                <mesh filename="package://human_model/meshes/pelvis-polyhedre6.dae"/>
            </geometry>
            <material name="pelvis_polyhedre6">
                <color rgba="1.000000 0.882353 0.000000 1.000000"/>
            </material>
        </visual>
    </link>
    <link name="pelvis+lHipY+lHipZ">
        <collision>
            <origin xyz="0.027581 -0.003062 -0.037279" rpy="0.000000 0.000000 90.000000"/>
            <geometry>
                <cylinder radius="0.181900" length="0.297400"/>
            </geometry>
        </collision>
        <visual>
            <origin xyz="0.000000 0.000000 0.000000" rpy="0.000000 0.000000 0.000000"/>
            <geometry>
                <mesh filename="package://human_model/meshes/pelvis-polyhedre1.dae"/>
            </geometry>
            <material name="pelvis_polyhedre1">
                <color rgba="0.901961 0.772549 0.694118 1.000000"/>
            </material>
        </visual>
        <visual>
            <origin xyz="0.000000 0.000000 0.000000" rpy="0.000000 0.000000 0.000000"/>
            <geometry>
                <mesh filename="package://human_model/meshes/pelvis-polyhedre2.dae"/>
            </geometry>
            <material name="pelvis_polyhedre2">
                <color rgba="0.992157 0.466667 0.466667 1.000000"/>
            </material>
        </visual>
        <visual>
            <origin xyz="0.000000 0.000000 0.000000" rpy="0.000000 0.000000 0.000000"/>
            <geometry>
                <mesh filename="package://human_model/meshes/pelvis-polyhedre3.dae"/>
            </geometry>
            <material name="pelvis_polyhedre3">
                <color rgba="0.190401 0.311497 0.805370 1.000000"/>
            </material>
        </visual>
        <visual>
            <origin xyz="0.000000 0.000000 0.000000" rpy="0.000000 0.000000 0.000000"/>
            <geometry>
                <mesh filename="package://human_model/meshes/pelvis-polyhedre4.dae"/>
            </geometry>
            <material name="pelvis_polyhedre4">
                <color rgba="0.323049 0.186374 0.136675 1.000000"/>
            </material>
        </visual>
        <visual>
            <origin xyz="0.000000 0.000000 0.000000" rpy="0.000000 0.000000 0.000000"/>
            <geometry>
                <mesh filename="package://human_model/meshes/pelvis-polyhedre5.dae"/>
            </geometry>
            <material name="pelvis_polyhedre5">
                <color rgba="0.062745 0.545098 0.796078 1.000000"/>
            </material>
        </visual>
        <visual>
            <origin xyz="0.000000 0.000000 0.000000" rpy="0.000000 0.000000 0.000000"/>
            <geometry>
                <mesh filename="package://human_model/meshes/pelvis-polyhedre6.dae"/>
            </geometry>
            <material name="pelvis_polyhedre6">
                <color rgba="1.000000 0.882353 0.000000 1.000000"/>
            </material>
        </visual>
    </link>
    <link name="lFemur">
        <collision>
            <origin xyz="0.024098 0.101405 -0.282207" rpy="0.000000 0.000000 90.000000"/>
            <geometry>
                <cylinder radius="0.100000" length="0.186700"/>
            </geometry>
        </collision>
        <collision>
            <origin xyz="0.010046 0.092430 -0.476062" rpy="5.200000 0.000000 90.000000"/>
            <geometry>
                <cylinder radius="0.089000" length="0.214900"/>
            </geometry>
        </collision>
        <visual>
            <origin xyz="0.000000 0.000000 0.000000" rpy="0.000000 0.000000 0.000000"/>
            <geometry>
                <mesh filename="package://human_model/meshes/lFemur-polyhedre1.dae"/>
            </geometry>
            <material name="lFemur_polyhedre1">
                <color rgba="0.190000 0.311000 0.805000 1.000000"/>
            </material>
        </visual>
    </link>
    <link name="lTibia">
        <collision>
            <origin xyz="-0.013396 0.097780 -0.759714" rpy="0.000000 0.000000 90.000000"/>
            <geometry>
                <cylinder radius="0.081700" length="0.349800"/>
            </geometry>
        </collision>
        <visual>
            <origin xyz="0.000000 0.000000 0.000000" rpy="0.000000 0.000000 0.000000"/>
            <geometry>
                <mesh filename="package://human_model/meshes/lTibia-polyhedre1.dae"/>
            </geometry>
            <material name="lTibia_polyhedre1">
                <color rgba="0.188235 0.309804 0.803922 1.000000"/>
            </material>
        </visual>
    </link>
    <link name="lTibia+lAnkleY">
        <collision>
            <origin xyz="-0.013396 0.097780 -0.759714" rpy="0.000000 0.000000 90.000000"/>
            <geometry>
                <cylinder radius="0.081700" length="0.349800"/>
            </geometry>
        </collision>
        <visual>
            <origin xyz="0.000000 0.000000 0.000000" rpy="0.000000 0.000000 0.000000"/>
            <geometry>
                <mesh filename="package://human_model/meshes/lTibia-polyhedre1.dae"/>
            </geometry>
            <material name="lTibia_polyhedre1">
                <color rgba="0.188235 0.309804 0.803922 1.000000"/>
            </material>
        </visual>
    </link>
    <link name="lTibia+lAnkleY+lAnkleZ">
        <collision>
            <origin xyz="-0.013396 0.097780 -0.759714" rpy="0.000000 0.000000 90.000000"/>
            <geometry>
                <cylinder radius="0.081700" length="0.349800"/>
            </geometry>
        </collision>
        <visual>
            <origin xyz="0.000000 0.000000 0.000000" rpy="0.000000 0.000000 0.000000"/>
            <geometry>
                <mesh filename="package://human_model/meshes/lTibia-polyhedre1.dae"/>
            </geometry>
            <material name="lTibia_polyhedre1">
                <color rgba="0.188235 0.309804 0.803922 1.000000"/>
            </material>
        </visual>
    </link>
    <link name="lFoot">
        <collision>
            <origin xyz="0.063501 0.094253 -0.992633" rpy="0.000000 0.000000 90.000000"/>
            <geometry>
                <box size="0.148800 0.328600 0.126100"/>
            </geometry>
        </collision>
        <visual>
            <origin xyz="0.000000 0.000000 0.000000" rpy="0.000000 0.000000 0.000000"/>
            <geometry>
                <mesh filename="package://human_model/meshes/lFoot-polyhedre1.dae"/>
            </geometry>
            <material name="lFoot_polyhedre1">
                <color rgba="1.000000 1.000000 1.000000 1.000000"/>
            </material>
        </visual>
        <visual>
            <origin xyz="0.000000 0.000000 0.000000" rpy="0.000000 0.000000 0.000000"/>
            <geometry>
                <mesh filename="package://human_model/meshes/lFoot-polyhedre2.dae"/>
            </geometry>
            <material name="lFoot_polyhedre2">
                <color rgba="0.619608 0.619608 0.619608 1.000000"/>
            </material>
        </visual>
        <visual>
            <origin xyz="0.000000 0.000000 0.000000" rpy="0.000000 0.000000 0.000000"/>
            <geometry>
                <mesh filename="package://human_model/meshes/lFoot-polyhedre3.dae"/>
            </geometry>
            <material name="lFoot_polyhedre3">
                <color rgba="0.000000 0.000000 0.000000 1.000000"/>
            </material>
        </visual>
        <visual>
            <origin xyz="0.000000 0.000000 0.000000" rpy="0.000000 0.000000 0.000000"/>
            <geometry>
                <mesh filename="package://human_model/meshes/lFoot-polyhedre4.dae"/>
            </geometry>
            <material name="lFoot_polyhedre4">
                <color rgba="0.164706 0.164706 0.447059 1.000000"/>
            </material>
        </visual>
        <visual>
            <origin xyz="0.000000 0.000000 0.000000" rpy="0.000000 0.000000 0.000000"/>
            <geometry>
                <mesh filename="package://human_model/meshes/lFoot-polyhedre5.dae"/>
            </geometry>
            <material name="lFoot_polyhedre5">
                <color rgba="0.568627 0.000000 0.000000 1.000000"/>
            </material>
        </visual>
    </link>
    <link name="rightreach">
        <visual>
            <origin xyz="0.000000 0.000000 0.000000" rpy="0.000000 180.000000 0.000000"/>
            <geometry>
                <sphere radius="0.010000"/>
            </geometry>
            <material name="rightreach_reachr">
                <color rgba="0.000000 0.000000 0.000000 0.000000"/>
            </material>
        </visual>
    </link>
    <link name="leftreach">
        <visual>
            <origin xyz="0.000000 0.000000 0.000000" rpy="0.000000 180.000000 0.000000"/>
            <geometry>
                <sphere radius="0.010000"/>
            </geometry>
            <material name="leftreach_reachs">
                <color rgba="0.000000 0.000000 0.000000 0.000000"/>
            </material>
        </visual>
    </link>


    <!-- Joints -->


    <!-- <joint name="Pelvis" type="floating">
        <origin xyz="0.000000 0.000000 0.000000" rpy="0 0 0"/>
        <axis xyz="0.000000 0.000000 0.000000"/>
        <child link="pelvis"/>
        <limit effort="0" lower="0" upper="0" velocity="0"/>
    </joint> -->
    <joint name="TorsoX" type="revolute">
        <origin xyz="0.037432 0.000000 0.139749" rpy="0 0 0"/>
        <axis xyz="1.000000 0.000000 0.000000"/>
        <parent link="pelvis"/>
        <child link="pelvis+TorsoY"/>
        <limit effort="0" lower="-0.785000" upper="0.785000" velocity="0"/>
    </joint>
    <joint name="TorsoY" type="revolute">
        <origin xyz="0.037432 0.000000 0.139749" rpy="0 0 0"/>
        <axis xyz="0.000000 1.000000 0.000000"/>
        <parent link="pelvis+TorsoY"/>
        <child link="pelvis+TorsoY+TorsoZ"/>
        <limit effort="0" lower="-0.348889" upper="0.697778" velocity="0"/>
    </joint>
    <joint name="TorsoZ" type="revolute">
        <origin xyz="0.037432 0.000000 0.139749" rpy="0 0 0"/>
        <axis xyz="0.000000 0.000000 1.000000"/>
        <parent link="pelvis+TorsoY+TorsoZ"/>
        <child link="torso"/>
        <limit effort="0" lower="-0.785000" upper="0.785000" velocity="0"/>
    </joint>
    <joint name="HeadZ" type="revolute">
        <origin xyz="0.023497 0.000000 0.593966" rpy="0 0 0"/>
        <axis xyz="0.000000 0.000000 1.000000"/>
        <parent link="torso"/>
        <child link="torso+HeadY"/>
        <limit effort="0" lower="-0.785000" upper="0.785000" velocity="0"/>
    </joint>
    <joint name="HeadY" type="revolute">
        <origin xyz="0.023497 0.000000 0.593966" rpy="0 0 0"/>
        <axis xyz="0.000000 -1.000000 0.000000"/>
        <parent link="torso+HeadY"/>
        <child link="head"/>
        <limit effort="0" lower="-1.046667" upper="0.523333" velocity="0"/>
    </joint>
    <!-- <joint name="HeadX" type="revolute">
        <origin xyz="0.023497 0.000000 0.593966" rpy="0 0 0"/>
        <axis xyz="1.000000 0.000000 0.000000"/>
        <parent link="head"/>
        <limit effort="0" lower="-0.785000" upper="0.785000" velocity="0"/>
    </joint> -->
    <joint name="rShoulderX" type="revolute">
        <origin xyz="-0.011200 -0.239820 0.428571" rpy="0 0 0"/>
        <axis xyz="1.000000 0.000000 0.000000"/>
        <parent link="torso"/>
        <child link="torso+rShoulderZ"/>
        <limit effort="0" lower="-3.140000" upper="3.140000" velocity="0"/>
    </joint>
    <joint name="rShoulderZ" type="revolute">
        <origin xyz="-0.011200 -0.239820 0.428571" rpy="0 0 0"/>
        <axis xyz="0.000000 0.000000 1.000000"/>
        <parent link="torso+rShoulderZ"/>
        <child link="torso+rShoulderZ+rShoulderY"/>
        <limit effort="0" lower="-3.140000" upper="3.140000" velocity="0"/>
    </joint>
    <joint name="rShoulderY" type="revolute">
        <origin xyz="-0.011200 -0.239820 0.428571" rpy="0 0 0"/>
        <axis xyz="0.000000 -1.000000 0.000000"/>
        <parent link="torso+rShoulderZ+rShoulderY"/>
        <child link="rHumerus"/>
        <limit effort="0" lower="-3.140000" upper="3.140000" velocity="0"/>
    </joint>
    <joint name="rArmTrans" type="prismatic">
        <origin xyz="-0.011200 -0.239820 0.428571" rpy="0 0 0"/>
        <axis xyz="1.000000 0.000000 0.000000"/>
        <parent link="rHumerus"/>
        <child link="rHumerus+rElbowZ"/>
        <limit effort="0" lower="-0.500000" upper="0.500000" velocity="0"/>
    </joint>
    <joint name="rElbowZ" type="revolute">
        <origin xyz="-0.007033 -0.446428 0.430224" rpy="0 0 0"/>
        <axis xyz="0.000000 0.000000 1.000000"/>
        <parent link="rHumerus+rElbowZ"/>
        <child link="rRadius"/>
        <limit effort="0" lower="-3.140000" upper="3.140000" velocity="0"/>
    </joint>
    <joint name="rPoint" type="prismatic">
        <origin xyz="-0.007033 -0.430224 -0.446428" rpy="0 0 0"/>
        <axis xyz="1.000000 0.000000 0.000000"/>
        <parent link="rRadius"/>
        <child link="rRadius+rWristX"/>
        <limit effort="0" lower="-0.500000" upper="0.500000" velocity="0"/>
    </joint>
    <joint name="rWristX" type="revolute">
        <origin xyz="-0.004259 -0.697000 0.434780" rpy="0 0 0"/>
        <axis xyz="1.000000 0.000000 0.000000"/>
        <parent link="rRadius+rWristX"/>
        <child link="rRadius+rWristX+rWristY"/>
        <limit effort="0" lower="-1.570000" upper="1.570000" velocity="0"/>
    </joint>
    <joint name="rWristY" type="revolute">
        <origin xyz="-0.004259 -0.697000 0.434780" rpy="0 0 0"/>
        <axis xyz="0.000000 1.000000 0.000000"/>
        <parent link="rRadius+rWristX+rWristY"/>
        <child link="rRadius+rWristX+rWristY+rWristZ"/>
        <limit effort="0" lower="-3.140000" upper="0.000000" velocity="0"/>
    </joint>
    <joint name="rWristZ" type="revolute">
        <origin xyz="-0.004259 -0.697000 0.434780" rpy="0 0 0"/>
        <axis xyz="0.000000 0.000000 1.000000"/>
        <parent link="rRadius+rWristX+rWristY+rWristZ"/>
        <child link="rHand"/>
        <limit effort="0" lower="-0.697778" upper="0.697778" velocity="0"/>
    </joint>
    <joint name="lShoulderX" type="revolute">
        <origin xyz="-0.011200 0.239820 0.428571" rpy="0 0 0"/>
        <axis xyz="1.000000 0.000000 0.000000"/>
        <parent link="torso"/>
        <child link="torso+lShoulderZ"/>
        <limit effort="0" lower="-3.140000" upper="3.140000" velocity="0"/>
    </joint>
    <joint name="lShoulderZ" type="revolute">
        <origin xyz="-0.011200 0.239820 0.428571" rpy="0 0 0"/>
        <axis xyz="0.000000 0.000000 1.000000"/>
        <parent link="torso+lShoulderZ"/>
        <child link="torso+lShoulderZ+lShoulderY"/>
        <limit effort="0" lower="-3.140000" upper="3.140000" velocity="0"/>
    </joint>
    <joint name="lShoulderY" type="revolute">
        <origin xyz="-0.011200 0.239820 0.428571" rpy="0 0 0"/>
        <axis xyz="0.000000 -1.000000 0.000000"/>
        <parent link="torso+lShoulderZ+lShoulderY"/>
        <child link="lHumerus"/>
        <limit effort="0" lower="-3.140000" upper="3.140000" velocity="0"/>
    </joint>
    <joint name="lArmTrans" type="prismatic">
        <origin xyz="-0.011200 -0.239820 -0.428571" rpy="0 0 0"/>
        <axis xyz="-1.000000 0.000000 0.000000"/>
        <parent link="lHumerus"/>
        <child link="lHumerus+lElbowZ"/>
        <limit effort="0" lower="-0.500000" upper="0.500000" velocity="0"/>
    </joint>
    <joint name="lElbowZ" type="revolute">
        <origin xyz="-0.007033 0.446428 0.430224" rpy="0 0 0"/>
        <axis xyz="0.000000 0.000000 1.000000"/>
        <parent link="lHumerus+lElbowZ"/>
        <child link="lRadius"/>
        <limit effort="0" lower="-3.140000" upper="3.140000" velocity="0"/>
    </joint>
    <joint name="lPoint" type="prismatic">
        <origin xyz="-0.007033 0.430224 -0.446428" rpy="0 0 0"/>
        <axis xyz="-1.000000 0.000000 0.000000"/>
        <parent link="lRadius"/>
        <child link="lRadius+lWristX"/>
        <limit effort="0" lower="-0.500000" upper="0.500000" velocity="0"/>
    </joint>
    <joint name="lWristX" type="revolute">
        <origin xyz="-0.004259 0.697000 0.434780" rpy="0 0 0"/>
        <axis xyz="1.000000 0.000000 0.000000"/>
        <parent link="lRadius+lWristX"/>
        <child link="lRadius+lWristX+lWristY"/>
        <limit effort="0" lower="-1.570000" upper="1.570000" velocity="0"/>
    </joint>
    <joint name="lWristY" type="revolute">
        <origin xyz="-0.004259 0.697000 0.434780" rpy="0 0 0"/>
        <axis xyz="0.000000 1.000000 0.000000"/>
        <parent link="lRadius+lWristX+lWristY"/>
        <child link="lRadius+lWristX+lWristY+lWristZ"/>
        <limit effort="0" lower="-3.140000" upper="0.000000" velocity="0"/>
    </joint>
    <joint name="lWristZ" type="revolute">
        <origin xyz="-0.004259 0.697000 0.434780" rpy="0 0 0"/>
        <axis xyz="0.000000 0.000000 1.000000"/>
        <parent link="lRadius+lWristX+lWristY+lWristZ"/>
        <child link="lHand"/>
        <limit effort="0" lower="-0.697778" upper="0.697778" velocity="0"/>
    </joint>
    <joint name="rHipX" type="revolute">
        <origin xyz="0.022487 -0.100975 -0.086017" rpy="0 0 0"/>
        <axis xyz="1.000000 0.000000 0.000000"/>
        <parent link="pelvis"/>
        <child link="pelvis+rHipY"/>
        <limit effort="0" lower="-1.744444" upper="0.174444" velocity="0"/>
    </joint>
    <joint name="rHipY" type="revolute">
        <origin xyz="0.022487 -0.100975 -0.086017" rpy="0 0 0"/>
        <axis xyz="0.000000 1.000000 0.000000"/>
        <parent link="pelvis+rHipY"/>
        <child link="pelvis+rHipY+rHipZ"/>
        <limit effort="0" lower="-2.616667" upper="1.046667" velocity="0"/>
    </joint>
    <joint name="rHipZ" type="revolute">
        <origin xyz="0.022487 -0.100975 -0.086017" rpy="0 0 0"/>
        <axis xyz="0.000000 0.000000 1.000000"/>
        <parent link="pelvis+rHipY+rHipZ"/>
        <child link="rFemur"/>
        <limit effort="0" lower="-0.697778" upper="0.697778" velocity="0"/>
    </joint>
    <joint name="rKnee" type="revolute">
        <origin xyz="-0.002421 -0.097751 -0.554311" rpy="0 0 0"/>
        <axis xyz="0.000000 1.000000 0.000000"/>
        <parent link="rFemur"/>
        <child link="rTibia"/>
        <limit effort="0" lower="0.000000" upper="2.442222" velocity="0"/>
    </joint>
    <joint name="rAnkleX" type="revolute">
        <origin xyz="-0.016412 -0.092302 -0.942910" rpy="0 0 0"/>
        <axis xyz="1.000000 0.000000 0.000000"/>
        <parent link="rTibia"/>
        <child link="rTibia+rAnkleY"/>
        <limit effort="0" lower="-0.348889" upper="0.348889" velocity="0"/>
    </joint>
    <joint name="rAnkleY" type="revolute">
        <origin xyz="-0.016412 -0.092302 -0.942910" rpy="0 0 0"/>
        <axis xyz="0.000000 1.000000 0.000000"/>
        <parent link="rTibia+rAnkleY"/>
        <child link="rTibia+rAnkleY+rAnkleZ"/>
        <limit effort="0" lower="-0.523333" upper="0.523333" velocity="0"/>
    </joint>
    <joint name="rAnkleZ" type="revolute">
        <origin xyz="-0.016412 -0.092302 -0.942910" rpy="0 0 0"/>
        <axis xyz="0.000000 0.000000 1.000000"/>
        <parent link="rTibia+rAnkleY+rAnkleZ"/>
        <child link="rFoot"/>
        <limit effort="0" lower="-0.697778" upper="0.697778" velocity="0"/>
    </joint>
    <joint name="lHipX" type="revolute">
        <origin xyz="0.022487 0.100975 -0.086017" rpy="0 0 0"/>
        <axis xyz="1.000000 0.000000 0.000000"/>
        <parent link="pelvis"/>
        <child link="pelvis+lHipY"/>
        <limit effort="0" lower="-0.174444" upper="1.744444" velocity="0"/>
    </joint>
    <joint name="lHipY" type="revolute">
        <origin xyz="0.022487 0.100975 -0.086017" rpy="0 0 0"/>
        <axis xyz="0.000000 1.000000 0.000000"/>
        <parent link="pelvis+lHipY"/>
        <child link="pelvis+lHipY+lHipZ"/>
        <limit effort="0" lower="-2.616667" upper="1.046667" velocity="0"/>
    </joint>
    <joint name="lHipZ" type="revolute">
        <origin xyz="0.022487 0.100975 -0.086017" rpy="0 0 0"/>
        <axis xyz="0.000000 0.000000 1.000000"/>
        <parent link="pelvis+lHipY+lHipZ"/>
        <child link="lFemur"/>
        <limit effort="0" lower="-0.697778" upper="0.697778" velocity="0"/>
    </joint>
    <joint name="lKnee" type="revolute">
        <origin xyz="-0.002421 0.097751 -0.554311" rpy="0 0 0"/>
        <axis xyz="0.000000 1.000000 0.000000"/>
        <parent link="lFemur"/>
        <child link="lTibia"/>
        <limit effort="0" lower="0.000000" upper="2.442222" velocity="0"/>
    </joint>
    <joint name="lAnkleX" type="revolute">
        <origin xyz="-0.016412 0.092302 -0.942910" rpy="0 0 0"/>
        <axis xyz="1.000000 0.000000 0.000000"/>
        <parent link="lTibia"/>
        <child link="lTibia+lAnkleY"/>
        <limit effort="0" lower="-0.348889" upper="0.348889" velocity="0"/>
    </joint>
    <joint name="lAnkleY" type="revolute">
        <origin xyz="-0.016412 0.092302 -0.942910" rpy="0 0 0"/>
        <axis xyz="0.000000 1.000000 0.000000"/>
        <parent link="lTibia+lAnkleY"/>
        <child link="lTibia+lAnkleY+lAnkleZ"/>
        <limit effort="0" lower="-0.523333" upper="0.523333" velocity="0"/>
    </joint>
    <joint name="lAnkleZ" type="revolute">
        <origin xyz="-0.016412 0.092302 -0.942910" rpy="0 0 0"/>
        <axis xyz="0.000000 0.000000 1.000000"/>
        <parent link="lTibia+lAnkleY+lAnkleZ"/>
        <child link="lFoot"/>
        <limit effort="0" lower="-0.697778" upper="0.697778" velocity="0"/>
    </joint>
    <joint name="rPalm" type="fixed">
        <origin xyz="-0.697000 -0.145741 0.434780" rpy="0 0 0"/>
        <axis xyz="0.000000 0.000000 -1.000000"/>
        <parent link="rHand"/>
        <child link="rightreach"/>
        <limit effort="0" lower="0" upper="0" velocity="0"/>
    </joint>
    <joint name="lPalm" type="fixed">
        <origin xyz="-0.697000 0.145741 0.434780" rpy="0 0 0"/>
        <axis xyz="0.000000 0.000000 1.000000"/>
        <parent link="lHand"/>
        <child link="leftreach"/>
        <limit effort="0" lower="0" upper="0" velocity="0"/>
    </joint>
</robot>
